<?xml version="1.0" encoding="UTF-8"?>
<testng-results retried="2" ignored="0" total="6" passed="2" failed="2" skipped="0">
  <reporter-output>
  </reporter-output>
  <suite started-at="2025-03-31T00:17:42 IST" name="Default suite" finished-at="2025-03-31T00:18:17 IST" duration-ms="35364">
    <groups>
      <group name="Regression">
        <method signature="ErrorValidationTest.validateOrderConfirmation()[pri:0, instance:Selenium.Testpackage.ErrorValidationTest@dd05255]" name="validateOrderConfirmation" class="Selenium.Testpackage.ErrorValidationTest"/>
        <method signature="ErrorValidationTest.validatecartProduct()[pri:0, instance:Selenium.Testpackage.ErrorValidationTest@dd05255]" name="validatecartProduct" class="Selenium.Testpackage.ErrorValidationTest"/>
      </group> <!-- Regression -->
      <group name="Smoke">
        <method signature="ErrorValidationTest.validateSignout(java.util.HashMap)[pri:0, instance:Selenium.Testpackage.ErrorValidationTest@dd05255]" name="validateSignout" class="Selenium.Testpackage.ErrorValidationTest"/>
      </group> <!-- Smoke -->
    </groups>
    <test started-at="2025-03-31T00:17:42 IST" name="Default test" finished-at="2025-03-31T00:18:17 IST" duration-ms="35364">
      <class name="Selenium.Testpackage.ErrorValidationTest">
        <test-method signature="validateOrderConfirmation()[pri:0, instance:Selenium.Testpackage.ErrorValidationTest@dd05255]" started-at="2025-03-31T00:17:42 IST" name="validateOrderConfirmation" finished-at="2025-03-31T00:17:54 IST" duration-ms="12209" status="PASS">
          <reporter-output>
          </reporter-output>
        </test-method> <!-- validateOrderConfirmation -->
        <test-method is-config="true" signature="close()[pri:0, instance:Selenium.Testpackage.ErrorValidationTest@dd05255]" started-at="2025-03-31T00:17:54 IST" name="close" finished-at="2025-03-31T00:17:54 IST" duration-ms="367" status="PASS">
          <reporter-output>
          </reporter-output>
        </test-method> <!-- close -->
        <test-method retried="true" signature="validateSignout(java.util.HashMap)[pri:0, instance:Selenium.Testpackage.ErrorValidationTest@dd05255]" started-at="2025-03-31T00:17:55 IST" name="validateSignout" data-provider="getData" finished-at="2025-03-31T00:17:58 IST" duration-ms="3672" status="SKIP">
          <params>
            <param index="0">
              <value>
                <![CDATA[{password=Password@135, email=rohit0007sethi@gmail.com}]]>
              </value>
            </param>
          </params>
          <exception class="java.lang.AssertionError">
            <message>
              <![CDATA[expected [LogoutSuccessfully] but found [Logout Successfully]]]>
            </message>
            <full-stacktrace>
              <![CDATA[java.lang.AssertionError: expected [LogoutSuccessfully] but found [Logout Successfully]
at org.testng.Assert.fail(Assert.java:111)
at org.testng.Assert.failNotEquals(Assert.java:1590)
at org.testng.Assert.assertEqualsImpl(Assert.java:150)
at org.testng.Assert.assertEquals(Assert.java:132)
at org.testng.Assert.assertEquals(Assert.java:656)
at org.testng.Assert.assertEquals(Assert.java:666)
at Selenium.Testpackage.ErrorValidationTest.validateSignout(ErrorValidationTest.java:31)
at java.base/jdk.internal.reflect.DirectMethodHandleAccessor.invoke(DirectMethodHandleAccessor.java:103)
at java.base/java.lang.reflect.Method.invoke(Method.java:580)
at org.testng.internal.invokers.MethodInvocationHelper.invokeMethod(MethodInvocationHelper.java:141)
at org.testng.internal.invokers.TestInvoker.invokeMethod(TestInvoker.java:687)
at org.testng.internal.invokers.TestInvoker.invokeTestMethod(TestInvoker.java:230)
at org.testng.internal.invokers.MethodRunner.runInSequence(MethodRunner.java:63)
at org.testng.internal.invokers.TestInvoker$MethodInvocationAgent.invoke(TestInvoker.java:995)
at org.testng.internal.invokers.TestInvoker.invokeTestMethods(TestInvoker.java:203)
at org.testng.internal.invokers.TestMethodWorker.invokeTestMethods(TestMethodWorker.java:154)
at org.testng.internal.invokers.TestMethodWorker.run(TestMethodWorker.java:134)
at java.base/java.util.ArrayList.forEach(ArrayList.java:1596)
at org.testng.TestRunner.privateRun(TestRunner.java:741)
at org.testng.TestRunner.run(TestRunner.java:616)
at org.testng.SuiteRunner.runTest(SuiteRunner.java:421)
at org.testng.SuiteRunner.runSequentially(SuiteRunner.java:413)
at org.testng.SuiteRunner.privateRun(SuiteRunner.java:373)
at org.testng.SuiteRunner.run(SuiteRunner.java:312)
at org.testng.SuiteRunnerWorker.runSuite(SuiteRunnerWorker.java:52)
at org.testng.SuiteRunnerWorker.run(SuiteRunnerWorker.java:95)
at org.testng.TestNG.runSuitesSequentially(TestNG.java:1274)
at org.testng.TestNG.runSuitesLocally(TestNG.java:1208)
at org.testng.TestNG.runSuites(TestNG.java:1112)
at org.testng.TestNG.run(TestNG.java:1079)
at org.testng.remote.AbstractRemoteTestNG.run(AbstractRemoteTestNG.java:115)
at org.testng.remote.RemoteTestNG.initAndRun(RemoteTestNG.java:293)
at org.testng.remote.RemoteTestNG.main(RemoteTestNG.java:91)
]]>
            </full-stacktrace>
          </exception> <!-- java.lang.AssertionError -->
          <reporter-output>
          </reporter-output>
        </test-method> <!-- validateSignout -->
        <test-method is-config="true" signature="close()[pri:0, instance:Selenium.Testpackage.ErrorValidationTest@dd05255]" started-at="2025-03-31T00:17:58 IST" name="close" finished-at="2025-03-31T00:17:59 IST" duration-ms="240" status="PASS">
          <reporter-output>
          </reporter-output>
        </test-method> <!-- close -->
        <test-method signature="validateSignout(java.util.HashMap)[pri:0, instance:Selenium.Testpackage.ErrorValidationTest@dd05255]" started-at="2025-03-31T00:17:59 IST" name="validateSignout" data-provider="getData" finished-at="2025-03-31T00:18:03 IST" duration-ms="3822" status="FAIL">
          <params>
            <param index="0">
              <value>
                <![CDATA[{password=Password@135, email=rohit0007sethi@gmail.com}]]>
              </value>
            </param>
          </params>
          <exception class="java.lang.AssertionError">
            <message>
              <![CDATA[expected [LogoutSuccessfully] but found [Logout Successfully]]]>
            </message>
            <full-stacktrace>
              <![CDATA[java.lang.AssertionError: expected [LogoutSuccessfully] but found [Logout Successfully]
at org.testng.Assert.fail(Assert.java:111)
at org.testng.Assert.failNotEquals(Assert.java:1590)
at org.testng.Assert.assertEqualsImpl(Assert.java:150)
at org.testng.Assert.assertEquals(Assert.java:132)
at org.testng.Assert.assertEquals(Assert.java:656)
at org.testng.Assert.assertEquals(Assert.java:666)
at Selenium.Testpackage.ErrorValidationTest.validateSignout(ErrorValidationTest.java:31)
at java.base/jdk.internal.reflect.DirectMethodHandleAccessor.invoke(DirectMethodHandleAccessor.java:103)
at java.base/java.lang.reflect.Method.invoke(Method.java:580)
at org.testng.internal.invokers.MethodInvocationHelper.invokeMethod(MethodInvocationHelper.java:141)
at org.testng.internal.invokers.TestInvoker.invokeMethod(TestInvoker.java:687)
at org.testng.internal.invokers.TestInvoker.retryFailed(TestInvoker.java:269)
at org.testng.internal.invokers.MethodRunner.runInSequence(MethodRunner.java:76)
at org.testng.internal.invokers.TestInvoker$MethodInvocationAgent.invoke(TestInvoker.java:995)
at org.testng.internal.invokers.TestInvoker.invokeTestMethods(TestInvoker.java:203)
at org.testng.internal.invokers.TestMethodWorker.invokeTestMethods(TestMethodWorker.java:154)
at org.testng.internal.invokers.TestMethodWorker.run(TestMethodWorker.java:134)
at java.base/java.util.ArrayList.forEach(ArrayList.java:1596)
at org.testng.TestRunner.privateRun(TestRunner.java:741)
at org.testng.TestRunner.run(TestRunner.java:616)
at org.testng.SuiteRunner.runTest(SuiteRunner.java:421)
at org.testng.SuiteRunner.runSequentially(SuiteRunner.java:413)
at org.testng.SuiteRunner.privateRun(SuiteRunner.java:373)
at org.testng.SuiteRunner.run(SuiteRunner.java:312)
at org.testng.SuiteRunnerWorker.runSuite(SuiteRunnerWorker.java:52)
at org.testng.SuiteRunnerWorker.run(SuiteRunnerWorker.java:95)
at org.testng.TestNG.runSuitesSequentially(TestNG.java:1274)
at org.testng.TestNG.runSuitesLocally(TestNG.java:1208)
at org.testng.TestNG.runSuites(TestNG.java:1112)
at org.testng.TestNG.run(TestNG.java:1079)
at org.testng.remote.AbstractRemoteTestNG.run(AbstractRemoteTestNG.java:115)
at org.testng.remote.RemoteTestNG.initAndRun(RemoteTestNG.java:293)
at org.testng.remote.RemoteTestNG.main(RemoteTestNG.java:91)
]]>
            </full-stacktrace>
          </exception> <!-- java.lang.AssertionError -->
          <reporter-output>
          </reporter-output>
        </test-method> <!-- validateSignout -->
        <test-method is-config="true" signature="close()[pri:0, instance:Selenium.Testpackage.ErrorValidationTest@dd05255]" started-at="2025-03-31T00:18:03 IST" name="close" finished-at="2025-03-31T00:18:03 IST" duration-ms="272" status="PASS">
          <reporter-output>
          </reporter-output>
        </test-method> <!-- close -->
        <test-method retried="true" signature="validateSignout(java.util.HashMap)[pri:0, instance:Selenium.Testpackage.ErrorValidationTest@dd05255]" started-at="2025-03-31T00:18:03 IST" name="validateSignout" data-provider="getData" finished-at="2025-03-31T00:18:06 IST" duration-ms="2962" status="SKIP">
          <params>
            <param index="0">
              <value>
                <![CDATA[{password=Password@135, email=mohit0007sethi@gmail.com}]]>
              </value>
            </param>
          </params>
          <exception class="java.lang.AssertionError">
            <message>
              <![CDATA[expected [LogoutSuccessfully] but found [Logout Successfully]]]>
            </message>
            <full-stacktrace>
              <![CDATA[java.lang.AssertionError: expected [LogoutSuccessfully] but found [Logout Successfully]
at org.testng.Assert.fail(Assert.java:111)
at org.testng.Assert.failNotEquals(Assert.java:1590)
at org.testng.Assert.assertEqualsImpl(Assert.java:150)
at org.testng.Assert.assertEquals(Assert.java:132)
at org.testng.Assert.assertEquals(Assert.java:656)
at org.testng.Assert.assertEquals(Assert.java:666)
at Selenium.Testpackage.ErrorValidationTest.validateSignout(ErrorValidationTest.java:31)
at java.base/jdk.internal.reflect.DirectMethodHandleAccessor.invoke(DirectMethodHandleAccessor.java:103)
at java.base/java.lang.reflect.Method.invoke(Method.java:580)
at org.testng.internal.invokers.MethodInvocationHelper.invokeMethod(MethodInvocationHelper.java:141)
at org.testng.internal.invokers.TestInvoker.invokeMethod(TestInvoker.java:687)
at org.testng.internal.invokers.TestInvoker.invokeTestMethod(TestInvoker.java:230)
at org.testng.internal.invokers.MethodRunner.runInSequence(MethodRunner.java:63)
at org.testng.internal.invokers.TestInvoker$MethodInvocationAgent.invoke(TestInvoker.java:995)
at org.testng.internal.invokers.TestInvoker.invokeTestMethods(TestInvoker.java:203)
at org.testng.internal.invokers.TestMethodWorker.invokeTestMethods(TestMethodWorker.java:154)
at org.testng.internal.invokers.TestMethodWorker.run(TestMethodWorker.java:134)
at java.base/java.util.ArrayList.forEach(ArrayList.java:1596)
at org.testng.TestRunner.privateRun(TestRunner.java:741)
at org.testng.TestRunner.run(TestRunner.java:616)
at org.testng.SuiteRunner.runTest(SuiteRunner.java:421)
at org.testng.SuiteRunner.runSequentially(SuiteRunner.java:413)
at org.testng.SuiteRunner.privateRun(SuiteRunner.java:373)
at org.testng.SuiteRunner.run(SuiteRunner.java:312)
at org.testng.SuiteRunnerWorker.runSuite(SuiteRunnerWorker.java:52)
at org.testng.SuiteRunnerWorker.run(SuiteRunnerWorker.java:95)
at org.testng.TestNG.runSuitesSequentially(TestNG.java:1274)
at org.testng.TestNG.runSuitesLocally(TestNG.java:1208)
at org.testng.TestNG.runSuites(TestNG.java:1112)
at org.testng.TestNG.run(TestNG.java:1079)
at org.testng.remote.AbstractRemoteTestNG.run(AbstractRemoteTestNG.java:115)
at org.testng.remote.RemoteTestNG.initAndRun(RemoteTestNG.java:293)
at org.testng.remote.RemoteTestNG.main(RemoteTestNG.java:91)
]]>
            </full-stacktrace>
          </exception> <!-- java.lang.AssertionError -->
          <reporter-output>
          </reporter-output>
        </test-method> <!-- validateSignout -->
        <test-method is-config="true" signature="close()[pri:0, instance:Selenium.Testpackage.ErrorValidationTest@dd05255]" started-at="2025-03-31T00:18:06 IST" name="close" finished-at="2025-03-31T00:18:06 IST" duration-ms="259" status="PASS">
          <reporter-output>
          </reporter-output>
        </test-method> <!-- close -->
        <test-method signature="validateSignout(java.util.HashMap)[pri:0, instance:Selenium.Testpackage.ErrorValidationTest@dd05255]" started-at="2025-03-31T00:18:06 IST" name="validateSignout" data-provider="getData" finished-at="2025-03-31T00:18:10 IST" duration-ms="3707" status="FAIL">
          <params>
            <param index="0">
              <value>
                <![CDATA[{password=Password@135, email=mohit0007sethi@gmail.com}]]>
              </value>
            </param>
          </params>
          <exception class="java.lang.AssertionError">
            <message>
              <![CDATA[expected [LogoutSuccessfully] but found [Logout Successfully]]]>
            </message>
            <full-stacktrace>
              <![CDATA[java.lang.AssertionError: expected [LogoutSuccessfully] but found [Logout Successfully]
at org.testng.Assert.fail(Assert.java:111)
at org.testng.Assert.failNotEquals(Assert.java:1590)
at org.testng.Assert.assertEqualsImpl(Assert.java:150)
at org.testng.Assert.assertEquals(Assert.java:132)
at org.testng.Assert.assertEquals(Assert.java:656)
at org.testng.Assert.assertEquals(Assert.java:666)
at Selenium.Testpackage.ErrorValidationTest.validateSignout(ErrorValidationTest.java:31)
at java.base/jdk.internal.reflect.DirectMethodHandleAccessor.invoke(DirectMethodHandleAccessor.java:103)
at java.base/java.lang.reflect.Method.invoke(Method.java:580)
at org.testng.internal.invokers.MethodInvocationHelper.invokeMethod(MethodInvocationHelper.java:141)
at org.testng.internal.invokers.TestInvoker.invokeMethod(TestInvoker.java:687)
at org.testng.internal.invokers.TestInvoker.retryFailed(TestInvoker.java:269)
at org.testng.internal.invokers.MethodRunner.runInSequence(MethodRunner.java:76)
at org.testng.internal.invokers.TestInvoker$MethodInvocationAgent.invoke(TestInvoker.java:995)
at org.testng.internal.invokers.TestInvoker.invokeTestMethods(TestInvoker.java:203)
at org.testng.internal.invokers.TestMethodWorker.invokeTestMethods(TestMethodWorker.java:154)
at org.testng.internal.invokers.TestMethodWorker.run(TestMethodWorker.java:134)
at java.base/java.util.ArrayList.forEach(ArrayList.java:1596)
at org.testng.TestRunner.privateRun(TestRunner.java:741)
at org.testng.TestRunner.run(TestRunner.java:616)
at org.testng.SuiteRunner.runTest(SuiteRunner.java:421)
at org.testng.SuiteRunner.runSequentially(SuiteRunner.java:413)
at org.testng.SuiteRunner.privateRun(SuiteRunner.java:373)
at org.testng.SuiteRunner.run(SuiteRunner.java:312)
at org.testng.SuiteRunnerWorker.runSuite(SuiteRunnerWorker.java:52)
at org.testng.SuiteRunnerWorker.run(SuiteRunnerWorker.java:95)
at org.testng.TestNG.runSuitesSequentially(TestNG.java:1274)
at org.testng.TestNG.runSuitesLocally(TestNG.java:1208)
at org.testng.TestNG.runSuites(TestNG.java:1112)
at org.testng.TestNG.run(TestNG.java:1079)
at org.testng.remote.AbstractRemoteTestNG.run(AbstractRemoteTestNG.java:115)
at org.testng.remote.RemoteTestNG.initAndRun(RemoteTestNG.java:293)
at org.testng.remote.RemoteTestNG.main(RemoteTestNG.java:91)
]]>
            </full-stacktrace>
          </exception> <!-- java.lang.AssertionError -->
          <reporter-output>
          </reporter-output>
        </test-method> <!-- validateSignout -->
        <test-method is-config="true" signature="close()[pri:0, instance:Selenium.Testpackage.ErrorValidationTest@dd05255]" started-at="2025-03-31T00:18:10 IST" name="close" finished-at="2025-03-31T00:18:10 IST" duration-ms="271" status="PASS">
          <reporter-output>
          </reporter-output>
        </test-method> <!-- close -->
        <test-method signature="validatecartProduct()[pri:0, instance:Selenium.Testpackage.ErrorValidationTest@dd05255]" started-at="2025-03-31T00:18:10 IST" name="validatecartProduct" finished-at="2025-03-31T00:18:17 IST" duration-ms="6751" status="PASS">
          <reporter-output>
          </reporter-output>
        </test-method> <!-- validatecartProduct -->
        <test-method is-config="true" signature="close()[pri:0, instance:Selenium.Testpackage.ErrorValidationTest@dd05255]" started-at="2025-03-31T00:18:17 IST" name="close" finished-at="2025-03-31T00:18:17 IST" duration-ms="268" status="PASS">
          <reporter-output>
          </reporter-output>
        </test-method> <!-- close -->
      </class> <!-- Selenium.Testpackage.ErrorValidationTest -->
    </test> <!-- Default test -->
  </suite> <!-- Default suite -->
</testng-results>
